Traceback (most recent call last):
  File "C:\ProgramData\Miniconda3\envs\gis\lib\site-packages\jupyter_cache\executors\utils.py", line 58, in single_nb_execution
    executenb(
  File "C:\ProgramData\Miniconda3\envs\gis\lib\site-packages\nbclient\client.py", line 1204, in execute
    return NotebookClient(nb=nb, resources=resources, km=km, **kwargs).execute()
  File "C:\ProgramData\Miniconda3\envs\gis\lib\site-packages\nbclient\util.py", line 84, in wrapped
    return just_run(coro(*args, **kwargs))
  File "C:\ProgramData\Miniconda3\envs\gis\lib\site-packages\nbclient\util.py", line 62, in just_run
    return loop.run_until_complete(coro)
  File "C:\ProgramData\Miniconda3\envs\gis\lib\asyncio\base_events.py", line 649, in run_until_complete
    return future.result()
  File "C:\ProgramData\Miniconda3\envs\gis\lib\site-packages\nbclient\client.py", line 663, in async_execute
    await self.async_execute_cell(
  File "C:\ProgramData\Miniconda3\envs\gis\lib\site-packages\nbclient\client.py", line 965, in async_execute_cell
    await self._check_raise_for_error(cell, cell_index, exec_reply)
  File "C:\ProgramData\Miniconda3\envs\gis\lib\site-packages\nbclient\client.py", line 862, in _check_raise_for_error
    raise CellExecutionError.from_cell_and_msg(cell, exec_reply_content)
nbclient.exceptions.CellExecutionError: An error occurred while executing the following cell:
------------------
# HIDDEN
import altair as alt

from tools import get_all_files, get_GHG_file_df
from tools.Plot_GHG import get_GHG_plots
------------------

[1;31m---------------------------------------------------------------------------[0m
[1;31mModuleNotFoundError[0m                       Traceback (most recent call last)
Cell [1;32mIn[2], line 4[0m
[0;32m      1[0m [38;5;66;03m# HIDDEN[39;00m
[0;32m      2[0m [38;5;28;01mimport[39;00m [38;5;21;01maltair[39;00m [38;5;28;01mas[39;00m [38;5;21;01malt[39;00m
[1;32m----> 4[0m [38;5;28;01mfrom[39;00m [38;5;21;01mtools[39;00m [38;5;28;01mimport[39;00m get_all_files, get_GHG_file_df
[0;32m      5[0m [38;5;28;01mfrom[39;00m [38;5;21;01mtools[39;00m[38;5;21;01m.[39;00m[38;5;21;01mPlot_GHG[39;00m [38;5;28;01mimport[39;00m get_GHG_plots

[1;31mModuleNotFoundError[0m: No module named 'tools'
ModuleNotFoundError: No module named 'tools'

